{
    "correct": 0,
    "error": "[NbClientApp] Executing .laborantum/texts/course/0-Warmup/3. Probability Theory/3. Discrete Probability Practice/task.ipynb\n0.00s - Debugger warning: It seems that frozen modules are being used, which may\n0.00s - make the debugger miss breakpoints. Please pass -Xfrozen_modules=off\n0.00s - to python to disable frozen modules.\n0.00s - Note: Debugging will proceed. Set PYDEVD_DISABLE_FILE_VALIDATION=1 to disable this validation.\n[NbClientApp] Executing notebook with kernel: container_env\nTraceback (most recent call last):\n  File \"/usr/local/lib/python3.11/site-packages/jupyter_core/utils/__init__.py\", line 154, in wrapped\n    asyncio.get_running_loop()\nRuntimeError: no running event loop\n\nDuring handling of the above exception, another exception occurred:\n\nTraceback (most recent call last):\n  File \"/usr/local/bin/jupyter-execute\", line 8, in <module>\n    sys.exit(main())\n             ^^^^^^\n  File \"/usr/local/lib/python3.11/site-packages/jupyter_core/application.py\", line 284, in launch_instance\n    super().launch_instance(argv=argv, **kwargs)\n  File \"/usr/local/lib/python3.11/site-packages/traitlets/config/application.py\", line 1074, in launch_instance\n    app.initialize(argv)\n  File \"/usr/local/lib/python3.11/site-packages/traitlets/config/application.py\", line 118, in inner\n    return method(app, *args, **kwargs)\n           ^^^^^^^^^^^^^^^^^^^^^^^^^^^^\n  File \"/usr/local/lib/python3.11/site-packages/nbclient/cli.py\", line 161, in initialize\n    self.run_notebook(path)\n  File \"/usr/local/lib/python3.11/site-packages/nbclient/cli.py\", line 215, in run_notebook\n    client.execute()\n  File \"/usr/local/lib/python3.11/site-packages/jupyter_core/utils/__init__.py\", line 158, in wrapped\n    return loop.run_until_complete(inner)\n           ^^^^^^^^^^^^^^^^^^^^^^^^^^^^^^\n  File \"/usr/local/lib/python3.11/asyncio/base_events.py\", line 654, in run_until_complete\n    return future.result()\n           ^^^^^^^^^^^^^^^\n  File \"/usr/local/lib/python3.11/site-packages/nbclient/client.py\", line 709, in async_execute\n    await self.async_execute_cell(\n  File \"/usr/local/lib/python3.11/site-packages/nbclient/client.py\", line 1062, in async_execute_cell\n    await self._check_raise_for_error(cell, cell_index, exec_reply)\n  File \"/usr/local/lib/python3.11/site-packages/nbclient/client.py\", line 918, in _check_raise_for_error\n    raise CellExecutionError.from_cell_and_msg(cell, exec_reply_content)\nnbclient.exceptions.CellExecutionError: An error occurred while executing the following cell:\n------------------\ntwo_dice = answer[0]\n\nprint(two_dice['p'])\n\nx_plus_y_p = {}\nfor x_index in range(two_dice['p'].shape[0]):\n    for y_index in range(two_dice['p'].shape[1]):\n        if x_index + 1 + y_index + 1 not in x_plus_y_p:\n            x_plus_y_p[x_index + 1 + y_index + 1] = 0\n        x_plus_y_p[x_index + 1 + y_index + 1] += two_dice['p'][x_index, y_index]\n\n# print(x_plus_y_p)\n# x_plus_y_p = dict(sorted(x_plus_y_p))\n# print(x_plus_y_p)\nplt.plot(list(x_plus_y_p.keys()), list(x_plus_y_p.values()), 'ro')\nplt.axvline(x=two_dice['Ex_plus_y'], color='r', linestyle='--', linewidth=2)\nplt.axvline(x=two_dice['Ex_plus_y'] - np.sqrt(two_dice['Vx_plus_y']), color='b', linestyle='--', linewidth=2)\nplt.axvline(x=two_dice['Ex_plus_y'] + np.sqrt(two_dice['Vx_plus_y']), color='b', linestyle='--', linewidth=2)\nplt.legend(['distribution', 'expectance', 'deviation'])\n------------------\n\n----- stdout -----\n0\n------------------\n\n\u001b[31m---------------------------------------------------------------------------\u001b[39m\n\u001b[31mAttributeError\u001b[39m                            Traceback (most recent call last)\n\u001b[36mCell\u001b[39m\u001b[36m \u001b[39m\u001b[32mIn[5]\u001b[39m\u001b[32m, line 6\u001b[39m\n\u001b[32m      3\u001b[39m \u001b[38;5;28mprint\u001b[39m(two_dice[\u001b[33m'\u001b[39m\u001b[33mp\u001b[39m\u001b[33m'\u001b[39m])\n\u001b[32m      5\u001b[39m x_plus_y_p = {}\n\u001b[32m----> \u001b[39m\u001b[32m6\u001b[39m \u001b[38;5;28;01mfor\u001b[39;00m x_index \u001b[38;5;129;01min\u001b[39;00m \u001b[38;5;28mrange\u001b[39m(\u001b[43mtwo_dice\u001b[49m\u001b[43m[\u001b[49m\u001b[33;43m'\u001b[39;49m\u001b[33;43mp\u001b[39;49m\u001b[33;43m'\u001b[39;49m\u001b[43m]\u001b[49m\u001b[43m.\u001b[49m\u001b[43mshape\u001b[49m[\u001b[32m0\u001b[39m]):\n\u001b[32m      7\u001b[39m     \u001b[38;5;28;01mfor\u001b[39;00m y_index \u001b[38;5;129;01min\u001b[39;00m \u001b[38;5;28mrange\u001b[39m(two_dice[\u001b[33m'\u001b[39m\u001b[33mp\u001b[39m\u001b[33m'\u001b[39m].shape[\u001b[32m1\u001b[39m]):\n\u001b[32m      8\u001b[39m         \u001b[38;5;28;01mif\u001b[39;00m x_index + \u001b[32m1\u001b[39m + y_index + \u001b[32m1\u001b[39m \u001b[38;5;129;01mnot\u001b[39;00m \u001b[38;5;129;01min\u001b[39;00m x_plus_y_p:\n\n\u001b[31mAttributeError\u001b[39m: 'int' object has no attribute 'shape'\n\n"
}